Workbook
Name AB_DIV: '4. Paramètres'!$C$62
Name ASSIETTE_CSG_SAL: '4. Paramètres'!$C$23
Name AUTRES_REV: '5. Profil'!$C$21
Name BENEFICE_IS: '5. Profil'!$C$28
Name CAPITAL_TNS: '5. Profil'!$C$16
Name CASHBACK_BADGE: '5. Profil'!$C$61
Name CASHBACK_MODE: '5. Profil'!$C$59
Name CDHR_SEUIL_C: '4. Paramètres'!$C$93
Name CDHR_SEUIL_C_HAUT: '4. Paramètres'!$C$95
Name CDHR_SEUIL_M: '4. Paramètres'!$C$94
Name CDHR_SEUIL_M_HAUT: '4. Paramètres'!$C$96
Name CDHR_TAUX_PLANCHER: '4. Paramètres'!$C$92
Name CEHR_SEUIL_C1: '4. Paramètres'!$C$85
Name CEHR_SEUIL_C2: '4. Paramètres'!$C$86
Name CEHR_SEUIL_M1: '4. Paramètres'!$C$87
Name CEHR_SEUIL_M2: '4. Paramètres'!$C$88
Name CEHR_TX_1: '4. Paramètres'!$C$83
Name CEHR_TX_2: '4. Paramètres'!$C$84
Name CLIENT_NAME: '5. Profil'!$C$5
Name DIVIDENDES_FOYER: '5. Profil'!$C$22
Name EFFECTIF: '5. Profil'!$C$14
Name ENVELOPPE: '5. Profil'!$C$27
Name FORME_JURIDIQUE: '5. Profil'!$C$12
Name FS_ABO_GE50: '4. Paramètres'!$C$42
Name FS_ABO_LT50: '4. Paramètres'!$C$41
Name FS_INT_GE250: '4. Paramètres'!$C$40
Name FS_INT_LT250: '4. Paramètres'!$C$39
Name FS_PART_50_249: '4. Paramètres'!$C$37
Name FS_PART_GE250: '4. Paramètres'!$C$38
Name FS_PART_LT50: '4. Paramètres'!$C$36
Name HORIZON_PROJ: '4. Paramètres'!$C$103
Name IR_PLAFOND_T1: '4. Paramètres'!$C$11
Name IR_PLAFOND_T2: '4. Paramètres'!$C$12
Name IR_PLAFOND_T3: '4. Paramètres'!$C$13
Name IR_PLAFOND_T4: '4. Paramètres'!$C$14
Name IR_TAUX_T2: '4. Paramètres'!$D$12
Name IR_TAUX_T3: '4. Paramètres'!$D$13
Name IR_TAUX_T4: '4. Paramètres'!$D$14
Name IR_TAUX_T5: '4. Paramètres'!$D$15
Name IS_PLAF_REDUIT: '4. Paramètres'!$C$69
Name M_ABO_PEE: '5. Profil'!$C$47
Name M_ABO_PER: '5. Profil'!$C$48
Name M_AVANTAGES: '5. Profil'!$C$50
Name M_CADO: '5. Profil'!$C$53
Name M_CASHBACK: '5. Profil'!$C$56
Name M_CESU: '5. Profil'!$C$52
Name M_IK: '5. Profil'!$C$55
Name M_INTERESSEMENT: '5. Profil'!$C$46
Name M_MUTUELLE: '5. Profil'!$C$54
Name M_PARTICIPATION: '5. Profil'!$C$45
Name M_PERIN: '5. Profil'!$C$49
Name M_TR: '5. Profil'!$C$51
Name MODE_PILOTAGE: '5. Profil'!$C$26
Name PARTS: '5. Profil'!$C$20
Name PASS_2025: '4. Paramètres'!$C$6
Name PLAF_QF_DEMI_PART: '4. Paramètres'!$C$74
Name PLAF_QF_INVALIDE: '4. Paramètres'!$C$78
Name PLAF_QF_PARENT_ISOLE: '4. Paramètres'!$C$75
Name PLAF_QF_PERS_SEULE_L: '4. Paramètres'!$C$76
Name PLAF_QF_VEUF: '4. Paramètres'!$C$77

Sheet 1. Garde
B3: Outil d'arbitrage de la rémunération du dirigeant
B4: Simulateur multi-population - TNS, assimilé salarié, libéral, salarié
B6: [Logo cabinet]
B10: Cabinet | D10: =INDEX('5. Profil'!C:C,MATCH("Cabinet",'5. Profil'!B:B,0))
B11: Client | D11: =CLIENT_NAME
B12: Date de la simulation | D12: =INDEX('5. Profil'!C:C,MATCH("Date de la simulation",'5. Profil'!B:B,0))
B13: Référentiel fiscal | D13: 2026 (revenus 2025)
B14: Version | D14: v19 - généré le 11/05/2026
B15: Historique | D15: v19 : Tests étendus 10→20 + 10 vérifications cohérence inter-feuilles automatiques
B17: SOMMAIRE
B18: 2. Dashboard | D18: 🟢 Synthèse rendez-vous client (1 page)
B19: 3. Mode d'emploi | D19: Logique de l'outil et codes couleurs
B20: 4. Paramètres fiscaux | D20: Référentiel 2026 (à mettre à jour annuellement)
B21: 5. Profil client | D21: Saisir les inputs du dossier
B22: 6. Comparateur | D22: Matrice de rentabilité par dispositif
B23: 7. Module Assimilé salarié | D23: Président SAS / SASU / SELAS, gérant min.
B24: 8. Module TNS | D24: Gérant majoritaire SARL/EURL, EI
B25: 9. Module Libéral | D25: BNC + SEL
B26: 10. Module Salarié | D26: Cadre / non-cadre - optimisation
B27: 11. Arbitrage global | D27: 4 stratégies à enveloppe constante
B28: 12. Synthèse dirigeant | D28: Livrable client final
B29: 13. Sources & disclaimer | D29: Références légales et limites
B32: AVERTISSEMENT
B33: Cet outil constitue une aide à la décision à usage professionnel et ne se substitue pas au conseil personnalisé d'un expert-comptable, d'un avocat fiscaliste ou d'un conseil en gestion de patrimoine. Les paramètres fiscaux et sociaux 2026 doivent être mis à jour annuellement (cf. feuille « 13. Sources »). Les calculs reposent sur des taux moyens indicatifs et des hypothèses simplificatrices documentées dans chaque module. Le cabinet décline toute responsabilité quant à l'usage qui pourrait en être fait.

Sheet 2. Dashboard
B2: Tableau de bord - arbitrage rémunération | G2: ↩ Sommaire
B3: Client : | C3: =CLIENT_NAME | E3: Régime : | F3: =REGIME_SOCIAL
B4: Date : | C4: =INDEX('5. Profil'!C:C,MATCH("Date de la simulation",'5. Profil'!B:B,0)) | E4: Effectif : | F4: =EFFECTIF
B5: 🎯 Stratégie recommandée | D5: =IF(MAX(INDEX('11. Arbitrage'!C:C,MATCH("TOTAL NET DIRIGEANT APRÈS FISCALITÉ (€)",'11. Arbitrage'!B:B,0)),INDEX('11. Arbitrage'!D:D,MATCH("TOTAL NET DIRIGEANT APRÈS FISCALITÉ (€)",'11. Arbitrage'!B:B,0)),INDEX('11. Arbitrage'!E:E,MATCH("TOTAL NET DIRIGEANT APRÈS FISCALITÉ (€)",'11. Arbitrage'!B:B,0)),INDEX('11. Arbitrage'!F:F,MATCH("TOTAL NET DIRIGEANT APRÈS FISCALITÉ (€)",'11. Arbitrage'!B:B,0)))=INDEX('11. Arbitrage'!C:C,MATCH("TOTAL NET DIRIGEANT APRÈS FISCALITÉ (€)",'11. Arbitrage'!B:B,0)),"A - 100 % rémunération directe",IF(MAX(INDEX('11. Arbitrage'!C:C,MATCH("TOTAL NET DIRIGEANT APRÈS FISCALITÉ (€)",'11. Arbitrage'!B:B,0)),INDEX('11. Arbitrage'!D:D,MATCH("TOTAL NET DIRIGEANT APRÈS FISCALITÉ (€)",'11. Arbitrage'!B:B,0)),INDEX('11. Arbitrage'!E:E,MATCH("TOTAL NET DIRIGEANT APRÈS FISCALITÉ (€)",'11. Arbitrage'!B:B,0)),INDEX('11. Arbitrage'!F:F,MATCH("TOTAL NET DIRIGEANT APRÈS FISCALITÉ (€)",'11. Arbitrage'!B:B,0)))=INDEX('11. Arbitrage'!D:D,MATCH("TOTAL NET DIRIGEANT APRÈS FISCALITÉ (€)",'11. Arbitrage'!B:B,0)),"B - Salaire optimisé + dividendes",IF(MAX(INDEX('11. Arbitrage'!C:C,MATCH("TOTAL NET DIRIGEANT APRÈS FISCALITÉ (€)",'11. Arbitrage'!B:B,0)),INDEX('11. Arbitrage'!D:D,MATCH("TOTAL NET DIRIGEANT APRÈS FISCALITÉ (€)",'11. Arbitrage'!B:B,0)),INDEX('11. Arbitrage'!E:E,MATCH("TOTAL NET DIRIGEANT APRÈS FISCALITÉ (€)",'11. Arbitrage'!B:B,0)),INDEX('11. Arbitrage'!F:F,MATCH("TOTAL NET DIRIGEANT APRÈS FISCALITÉ (€)",'11. Arbitrage'!B:B,0)))=INDEX('11. Arbitrage'!E:E,MATCH("TOTAL NET DIRIGEANT APRÈS FISCALITÉ (€)",'11. Arbitrage'!B:B,0)),"C - + Épargne salariale & PER","D - Stratégie complète + périphériques")))
B6: Stratégie sélectionnée | C6: Reco automatique (max net dirigeant) | E6: Stratégie retenue : | F6: =IF($C$6="Reco automatique (max net dirigeant)",IF(MAX(INDEX('11. Arbitrage'!C:C,MATCH("TOTAL NET DIRIGEANT APRÈS FISCALITÉ (€)",'11. Arbitrage'!B:B,0)),INDEX('11. Arbitrage'!D:D,MATCH("TOTAL NET DIRIGEANT APRÈS FISCALITÉ (€)",'11. Arbitrage'!B:B,0)),INDEX('11. Arbitrage'!E:E,MATCH("TOTAL NET DIRIGEANT APRÈS FISCALITÉ (€)",'11. Arbitrage'!B:B,0)),INDEX('11. Arbitrage'!F:F,MATCH("TOTAL NET DIRIGEANT APRÈS FISCALITÉ (€)",'11. Arbitrage'!B:B,0)))=INDEX('11. Arbitrage'!C:C,MATCH("TOTAL NET DIRIGEANT APRÈS FISCALITÉ (€)",'11. Arbitrage'!B:B,0)),"A",IF(MAX(INDEX('11. Arbitrage'!C:C,MATCH("TOTAL NET DIRIGEANT APRÈS FISCALITÉ (€)",'11. Arbitrage'!B:B,0)),INDEX('11. Arbitrage'!D:D,MATCH("TOTAL NET DIRIGEANT APRÈS FISCALITÉ (€)",'11. Arbitrage'!B:B,0)),INDEX('11. Arbitrage'!E:E,MATCH("TOTAL NET DIRIGEANT APRÈS FISCALITÉ (€)",'11. Arbitrage'!B:B,0)),INDEX('11. Arbitrage'!F:F,MATCH("TOTAL NET DIRIGEANT APRÈS FISCALITÉ (€)",'11. Arbitrage'!B:B,0)))=INDEX('11. Arbitrage'!D:D,MATCH("TOTAL NET DIRIGEANT APRÈS FISCALITÉ (€)",'11. Arbitrage'!B:B,0)),"B",IF(MAX(INDEX('11. Arbitrage'!C:C,MATCH("TOTAL NET DIRIGEANT APRÈS FISCALITÉ (€)",'11. Arbitrage'!B:B,0)),INDEX('11. Arbitrage'!D:D,MATCH("TOTAL NET DIRIGEANT APRÈS FISCALITÉ (€)",'11. Arbitrage'!B:B,0)),INDEX('11. Arbitrage'!E:E,MATCH("TOTAL NET DIRIGEANT APRÈS FISCALITÉ (€)",'11. Arbitrage'!B:B,0)),INDEX('11. Arbitrage'!F:F,MATCH("TOTAL NET DIRIGEANT APRÈS FISCALITÉ (€)",'11. Arbitrage'!B:B,0)))=INDEX('11. Arbitrage'!E:E,MATCH("TOTAL NET DIRIGEANT APRÈS FISCALITÉ (€)",'11. Arbitrage'!B:B,0)),"C","D"))),LEFT($C$6,1)) | G6: ← lettre A/B/C/D
B7: Statut de la sélection | C7: =IF($C$6="Reco automatique (max net dirigeant)","✓ Mode automatique - stratégie alignée sur la reco ("&IF(MAX(INDEX('11. Arbitrage'!C:C,MATCH("TOTAL NET DIRIGEANT APRÈS FISCALITÉ (€)",'11. Arbitrage'!B:B,0)),INDEX('11. Arbitrage'!D:D,MATCH("TOTAL NET DIRIGEANT APRÈS FISCALITÉ (€)",'11. Arbitrage'!B:B,0)),INDEX('11. Arbitrage'!E:E,MATCH("TOTAL NET DIRIGEANT APRÈS FISCALITÉ (€)",'11. Arbitrage'!B:B,0)),INDEX('11. Arbitrage'!F:F,MATCH("TOTAL NET DIRIGEANT APRÈS FISCALITÉ (€)",'11. Arbitrage'!B:B,0)))=INDEX('11. Arbitrage'!C:C,MATCH("TOTAL NET DIRIGEANT APRÈS FISCALITÉ (€)",'11. Arbitrage'!B:B,0)),"A",IF(MAX(INDEX('11. Arbitrage'!C:C,MATCH("TOTAL NET DIRIGEANT APRÈS FISCALITÉ (€)",'11. Arbitrage'!B:B,0)),INDEX('11. Arbitrage'!D:D,MATCH("TOTAL NET DIRIGEANT APRÈS FISCALITÉ (€)",'11. Arbitrage'!B:B,0)),INDEX('11. Arbitrage'!E:E,MATCH("TOTAL NET DIRIGEANT APRÈS FISCALITÉ (€)",'11. Arbitrage'!B:B,0)),INDEX('11. Arbitrage'!F:F,MATCH("TOTAL NET DIRIGEANT APRÈS FISCALITÉ (€)",'11. Arbitrage'!B:B,0)))=INDEX('11. Arbitrage'!D:D,MATCH("TOTAL NET DIRIGEANT APRÈS FISCALITÉ (€)",'11. Arbitrage'!B:B,0)),"B",IF(MAX(INDEX('11. Arbitrage'!C:C,MATCH("TOTAL NET DIRIGEANT APRÈS FISCALITÉ (€)",'11. Arbitrage'!B:B,0)),INDEX('11. Arbitrage'!D:D,MATCH("TOTAL NET DIRIGEANT APRÈS FISCALITÉ (€)",'11. Arbitrage'!B:B,0)),INDEX('11. Arbitrage'!E:E,MATCH("TOTAL NET DIRIGEANT APRÈS FISCALITÉ (€)",'11. Arbitrage'!B:B,0)),INDEX('11. Arbitrage'!F:F,MATCH("TOTAL NET DIRIGEANT APRÈS FISCALITÉ (€)",'11. Arbitrage'!B:B,0)))=INDEX('11. Arbitrage'!E:E,MATCH("TOTAL NET DIRIGEANT APRÈS FISCALITÉ (€)",'11. Arbitrage'!B:B,0)),"C","D")))&")",IF(LEFT($C$6,1)=IF(MAX(INDEX('11. Arbitrage'!C:C,MATCH("TOTAL NET DIRIGEANT APRÈS FISCALITÉ (€)",'11. Arbitrage'!B:B,0)),INDEX('11. Arbitrage'!D:D,MATCH("TOTAL NET DIRIGEANT APRÈS FISCALITÉ (€)",'11. Arbitrage'!B:B,0)),INDEX('11. Arbitrage'!E:E,MATCH("TOTAL NET DIRIGEANT APRÈS FISCALITÉ (€)",'11. Arbitrage'!B:B,0)),INDEX('11. Arbitrage'!F:F,MATCH("TOTAL NET DIRIGEANT APRÈS FISCALITÉ (€)",'11. Arbitrage'!B:B,0)))=INDEX('11. Arbitrage'!C:C,MATCH("TOTAL NET DIRIGEANT APRÈS FISCALITÉ (€)",'11. Arbitrage'!B:B,0)),"A",IF(MAX(INDEX('11. Arbitrage'!C:C,MATCH("TOTAL NET DIRIGEANT APRÈS FISCALITÉ (€)",'11. Arbitrage'!B:B,0)),INDEX('11. Arbitrage'!D:D,MATCH("TOTAL NET DIRIGEANT APRÈS FISCALITÉ (€)",'11. Arbitrage'!B:B,0)),INDEX('11. Arbitrage'!E:E,MATCH("TOTAL NET DIRIGEANT APRÈS FISCALITÉ (€)",'11. Arbitrage'!B:B,0)),INDEX('11. Arbitrage'!F:F,MATCH("TOTAL NET DIRIGEANT APRÈS FISCALITÉ (€)",'11. Arbitrage'!B:B,0)))=INDEX('11. Arbitrage'!D:D,MATCH("TOTAL NET DIRIGEANT APRÈS FISCALITÉ (€)",'11. Arbitrage'!B:B,0)),"B",IF(MAX(INDEX('11. Arbitrage'!C:C,MATCH("TOTAL NET DIRIGEANT APRÈS FISCALITÉ (€)",'11. Arbitrage'!B:B,0)),INDEX('11. Arbitrage'!D:D,MATCH("TOTAL NET DIRIGEANT APRÈS FISCALITÉ (€)",'11. Arbitrage'!B:B,0)),INDEX('11. Arbitrage'!E:E,MATCH("TOTAL NET DIRIGEANT APRÈS FISCALITÉ (€)",'11. Arbitrage'!B:B,0)),INDEX('11. Arbitrage'!F:F,MATCH("TOTAL NET DIRIGEANT APRÈS FISCALITÉ (€)",'11. Arbitrage'!B:B,0)))=INDEX('11. Arbitrage'!E:E,MATCH("TOTAL NET DIRIGEANT APRÈS FISCALITÉ (€)",'11. Arbitrage'!B:B,0)),"C","D"))),"✓ Sélection manuelle alignée sur la reco ("&IF(MAX(INDEX('11. Arbitrage'!C:C,MATCH("TOTAL NET DIRIGEANT APRÈS FISCALITÉ (€)",'11. Arbitrage'!B:B,0)),INDEX('11. Arbitrage'!D:D,MATCH("TOTAL NET DIRIGEANT APRÈS FISCALITÉ (€)",'11. Arbitrage'!B:B,0)),INDEX('11. Arbitrage'!E:E,MATCH("TOTAL NET DIRIGEANT APRÈS FISCALITÉ (€)",'11. Arbitrage'!B:B,0)),INDEX('11. Arbitrage'!F:F,MATCH("TOTAL NET DIRIGEANT APRÈS FISCALITÉ (€)",'11. Arbitrage'!B:B,0)))=INDEX('11. Arbitrage'!C:C,MATCH("TOTAL NET DIRIGEANT APRÈS FISCALITÉ (€)",'11. Arbitrage'!B:B,0)),"A",IF(MAX(INDEX('11. Arbitrage'!C:C,MATCH("TOTAL NET DIRIGEANT APRÈS FISCALITÉ (€)",'11. Arbitrage'!B:B,0)),INDEX('11. Arbitrage'!D:D,MATCH("TOTAL NET DIRIGEANT APRÈS FISCALITÉ (€)",'11. Arbitrage'!B:B,0)),INDEX('11. Arbitrage'!E:E,MATCH("TOTAL NET DIRIGEANT APRÈS FISCALITÉ (€)",'11. Arbitrage'!B:B,0)),INDEX('11. Arbitrage'!F:F,MATCH("TOTAL NET DIRIGEANT APRÈS FISCALITÉ (€)",'11. Arbitrage'!B:B,0)))=INDEX('11. Arbitrage'!D:D,MATCH("TOTAL NET DIRIGEANT APRÈS FISCALITÉ (€)",'11. Arbitrage'!B:B,0)),"B",IF(MAX(INDEX('11. Arbitrage'!C:C,MATCH("TOTAL NET DIRIGEANT APRÈS FISCALITÉ (€)",'11. Arbitrage'!B:B,0)),INDEX('11. Arbitrage'!D:D,MATCH("TOTAL NET DIRIGEANT APRÈS FISCALITÉ (€)",'11. Arbitrage'!B:B,0)),INDEX('11. Arbitrage'!E:E,MATCH("TOTAL NET DIRIGEANT APRÈS FISCALITÉ (€)",'11. Arbitrage'!B:B,0)),INDEX('11. Arbitrage'!F:F,MATCH("TOTAL NET DIRIGEANT APRÈS FISCALITÉ (€)",'11. Arbitrage'!B:B,0)))=INDEX('11. Arbitrage'!E:E,MATCH("TOTAL NET DIRIGEANT APRÈS FISCALITÉ (€)",'11. Arbitrage'!B:B,0)),"C","D")))&")","⚠ Écart vs reco - la reco automatique est "&IF(MAX(INDEX('11. Arbitrage'!C:C,MATCH("TOTAL NET DIRIGEANT APRÈS FISCALITÉ (€)",'11. Arbitrage'!B:B,0)),INDEX('11. Arbitrage'!D:D,MATCH("TOTAL NET DIRIGEANT APRÈS FISCALITÉ (€)",'11. Arbitrage'!B:B,0)),INDEX('11. Arbitrage'!E:E,MATCH("TOTAL NET DIRIGEANT APRÈS FISCALITÉ (€)",'11. Arbitrage'!B:B,0)),INDEX('11. Arbitrage'!F:F,MATCH("TOTAL NET DIRIGEANT APRÈS FISCALITÉ (€)",'11. Arbitrage'!B:B,0)))=INDEX('11. Arbitrage'!C:C,MATCH("TOTAL NET DIRIGEANT APRÈS FISCALITÉ (€)",'11. Arbitrage'!B:B,0)),"A",IF(MAX(INDEX('11. Arbitrage'!C:C,MATCH("TOTAL NET DIRIGEANT APRÈS FISCALITÉ (€)",'11. Arbitrage'!B:B,0)),INDEX('11. Arbitrage'!D:D,MATCH("TOTAL NET DIRIGEANT APRÈS FISCALITÉ (€)",'11. Arbitrage'!B:B,0)),INDEX('11. Arbitrage'!E:E,MATCH("TOTAL NET DIRIGEANT APRÈS FISCALITÉ (€)",'11. Arbitrage'!B:B,0)),INDEX('11. Arbitrage'!F:F,MATCH("TOTAL NET DIRIGEANT APRÈS FISCALITÉ (€)",'11. Arbitrage'!B:B,0)))=INDEX('11. Arbitrage'!D:D,MATCH("TOTAL NET DIRIGEANT APRÈS FISCALITÉ (€)",'11. Arbitrage'!B:B,0)),"B",IF(MAX(INDEX('11. Arbitrage'!C:C,MATCH("TOTAL NET DIRIGEANT APRÈS FISCALITÉ (€)",'11. Arbitrage'!B:B,0)),INDEX('11. Arbitrage'!D:D,MATCH("TOTAL NET DIRIGEANT APRÈS FISCALITÉ (€)",'11. Arbitrage'!B:B,0)),INDEX('11. Arbitrage'!E:E,MATCH("TOTAL NET DIRIGEANT APRÈS FISCALITÉ (€)",'11. Arbitrage'!B:B,0)),INDEX('11. Arbitrage'!F:F,MATCH("TOTAL NET DIRIGEANT APRÈS FISCALITÉ (€)",'11. Arbitrage'!B:B,0)))=INDEX('11. Arbitrage'!E:E,MATCH("TOTAL NET DIRIGEANT APRÈS FISCALITÉ (€)",'11. Arbitrage'!B:B,0)),"C","D")))&" (vous avez choisi "&LEFT($C$6,1)&")"))
B8: COÛT TOTAL SOCIÉTÉ | E8: NET DIRIGEANT
B9: =ENVELOPPE | E9: =IF($F$6="A",INDEX('11. Arbitrage'!C:C,MATCH("TOTAL NET DIRIGEANT APRÈS FISCALITÉ (€)",'11. Arbitrage'!B:B,0)),IF($F$6="B",INDEX('11. Arbitrage'!D:D,MATCH("TOTAL NET DIRIGEANT APRÈS FISCALITÉ (€)",'11. Arbitrage'!B:B,0)),IF($F$6="C",INDEX('11. Arbitrage'!E:E,MATCH("TOTAL NET DIRIGEANT APRÈS FISCALITÉ (€)",'11. Arbitrage'!B:B,0)),INDEX('11. Arbitrage'!F:F,MATCH("TOTAL NET DIRIGEANT APRÈS FISCALITÉ (€)",'11. Arbitrage'!B:B,0)))))
B11: GAIN vs STRATÉGIE A | E11: EFFICACITÉ FISCALE
B12: =IF($F$6="A",INDEX('11. Arbitrage'!C:C,MATCH("TOTAL NET DIRIGEANT APRÈS FISCALITÉ (€)",'11. Arbitrage'!B:B,0)),IF($F$6="B",INDEX('11. Arbitrage'!D:D,MATCH("TOTAL NET DIRIGEANT APRÈS FISCALITÉ (€)",'11. Arbitrage'!B:B,0)),IF($F$6="C",INDEX('11. Arbitrage'!E:E,MATCH("TOTAL NET DIRIGEANT APRÈS FISCALITÉ (€)",'11. Arbitrage'!B:B,0)),INDEX('11. Arbitrage'!F:F,MATCH("TOTAL NET DIRIGEANT APRÈS FISCALITÉ (€)",'11. Arbitrage'!B:B,0)))))-INDEX('11. Arbitrage'!C:C,MATCH("TOTAL NET DIRIGEANT APRÈS FISCALITÉ (€)",'11. Arbitrage'!B:B,0)) | E12: =IFERROR((IF($F$6="A",INDEX('11. Arbitrage'!C:C,MATCH("TOTAL NET DIRIGEANT APRÈS FISCALITÉ (€)",'11. Arbitrage'!B:B,0)),IF($F$6="B",INDEX('11. Arbitrage'!D:D,MATCH("TOTAL NET DIRIGEANT APRÈS FISCALITÉ (€)",'11. Arbitrage'!B:B,0)),IF($F$6="C",INDEX('11. Arbitrage'!E:E,MATCH("TOTAL NET DIRIGEANT APRÈS FISCALITÉ (€)",'11. Arbitrage'!B:B,0)),INDEX('11. Arbitrage'!F:F,MATCH("TOTAL NET DIRIGEANT APRÈS FISCALITÉ (€)",'11. Arbitrage'!B:B,0))))))/ENVELOPPE,0)
B14: Lecture en une phrase
B15: ="Avec un budget de "&TEXT(ROUND(ENVELOPPE,0),"# ##0")&" €, la stratégie "&$F$6&" génère "&TEXT(ROUND(IF($F$6="A",INDEX('11. Arbitrage'!C:C,MATCH("TOTAL NET DIRIGEANT APRÈS FISCALITÉ (€)",'11. Arbitrage'!B:B,0)),IF($F$6="B",INDEX('11. Arbitrage'!D:D,MATCH("TOTAL NET DIRIGEANT APRÈS FISCALITÉ (€)",'11. Arbitrage'!B:B,0)),IF($F$6="C",INDEX('11. Arbitrage'!E:E,MATCH("TOTAL NET DIRIGEANT APRÈS FISCALITÉ (€)",'11. Arbitrage'!B:B,0)),INDEX('11. Arbitrage'!F:F,MATCH("TOTAL NET DIRIGEANT APRÈS FISCALITÉ (€)",'11. Arbitrage'!B:B,0))))),0),"# ##0")&" € nets pour le dirigeant, soit un gain de "&TEXT(ROUND((IF($F$6="A",INDEX('11. Arbitrage'!C:C,MATCH("TOTAL NET DIRIGEANT APRÈS FISCALITÉ (€)",'11. Arbitrage'!B:B,0)),IF($F$6="B",INDEX('11. Arbitrage'!D:D,MATCH("TOTAL NET DIRIGEANT APRÈS FISCALITÉ (€)",'11. Arbitrage'!B:B,0)),IF($F$6="C",INDEX('11. Arbitrage'!E:E,MATCH("TOTAL NET DIRIGEANT APRÈS FISCALITÉ (€)",'11. Arbitrage'!B:B,0)),INDEX('11. Arbitrage'!F:F,MATCH("TOTAL NET DIRIGEANT APRÈS FISCALITÉ (€)",'11. Arbitrage'!B:B,0))))))-INDEX('11. Arbitrage'!C:C,MATCH("TOTAL NET DIRIGEANT APRÈS FISCALITÉ (€)",'11. Arbitrage'!B:B,0)),0),"+# ##0;-# ##0;0")&" €"&" ("&IF(INDEX('11. Arbitrage'!C:C,MATCH("TOTAL NET DIRIGEANT APRÈS FISCALITÉ (€)",'11. Arbitrage'!B:B,0))>0,TEXT((IF($F$6="A",INDEX('11. Arbitrage'!C:C,MATCH("TOTAL NET DIRIGEANT APRÈS FISCALITÉ (€)",'11. Arbitrage'!B:B,0)),IF($F$6="B",INDEX('11. Arbitrage'!D:D,MATCH("TOTAL NET DIRIGEANT APRÈS FISCALITÉ (€)",'11. Arbitrage'!B:B,0)),IF($F$6="C",INDEX('11. Arbitrage'!E:E,MATCH("TOTAL NET DIRIGEANT APRÈS FISCALITÉ (€)",'11. Arbitrage'!B:B,0)),INDEX('11. Arbitrage'!F:F,MATCH("TOTAL NET DIRIGEANT APRÈS FISCALITÉ (€)",'11. Arbitrage'!B:B,0))))))/INDEX('11. Arbitrage'!C:C,MATCH("TOTAL NET DIRIGEANT APRÈS FISCALITÉ (€)",'11. Arbitrage'!B:B,0))-1,"+0,0%;-0,0%"),"-")&") vs Stratégie A - salaire classique ("&TEXT(ROUND(INDEX('11. Arbitrage'!C:C,MATCH("TOTAL NET DIRIGEANT APRÈS FISCALITÉ (€)",'11. Arbitrage'!B:B,0)),0),"# ##0")&" € nets)."
B19: Podium - top 3 dispositifs (score ajusté du Comparateur)
B20: 🥇 | C20: =IFERROR(INDEX('6. Comparateur'!B:B,MATCH("🥇",'6. Comparateur'!N:N,0)),"-") | F20: =IFERROR(INDEX('6. Comparateur'!M:M,MATCH("🥇",'6. Comparateur'!N:N,0)),"-") | G20: =IFERROR(INDEX('6. Comparateur'!L:L,MATCH("🥇",'6. Comparateur'!N:N,0)),"-")
B21: 🥈 | C21: =IFERROR(INDEX('6. Comparateur'!B:B,MATCH("🥈",'6. Comparateur'!N:N,0)),"-") | F21: =IFERROR(INDEX('6. Comparateur'!M:M,MATCH("🥈",'6. Comparateur'!N:N,0)),"-") | G21: =IFERROR(INDEX('6. Comparateur'!L:L,MATCH("🥈",'6. Comparateur'!N:N,0)),"-")
B22: 🥉 | C22: =IFERROR(INDEX('6. Comparateur'!B:B,MATCH("🥉",'6. Comparateur'!N:N,0)),"-") | F22: =IFERROR(INDEX('6. Comparateur'!M:M,MATCH("🥉",'6. Comparateur'!N:N,0)),"-") | G22: =IFERROR(INDEX('6. Comparateur'!L:L,MATCH("🥉",'6. Comparateur'!N:N,0)),"-")
B24: =("Composition de la stratégie sélectionnée - "&$F$6)
B25: Inclus | C25: Dispositif | E25: Montant | F25: Risque | G25: Commentaire
B26: =IF(AND(TOG_PARTICIPATION="Oui",$F$6>="B"),"✓","") | C26: Participation | E26: =IF(AND(TOG_PARTICIPATION="Oui",$F$6>="B"),M_PARTICIPATION,"") | F26: 🟢 Sécurisé | G26: Cadre légal stable, exo IR si placement 5 ans en PEE.
B27: =IF(AND(TOG_INTERESSEMENT="Oui",$F$6>="B"),"✓","") | C27: Intéressement | E27: =IF(AND(TOG_INTERESSEMENT="Oui",$F$6>="B"),M_INTERESSEMENT,"") | F27: 🟢 Sécurisé | G27: Accord triennal ; aléatoire et collectif.
B28: =IF(AND(TOG_ABO_PEE="Oui",$F$6>="B"),"✓","") | C28: Abondement PEE | E28: =IF(AND(TOG_ABO_PEE="Oui",$F$6>="B"),M_ABO_PEE,"") | F28: 🟢 Sécurisé | G28: Plafond 8 % PASS, triplement contributions salarié.
B29: =IF(AND(TOG_ABO_PER="Oui",$F$6>="B"),"✓","") | C29: Abondement PER collectif | E29: =IF(AND(TOG_ABO_PER="Oui",$F$6>="B"),M_ABO_PER,"") | F29: 🟢 Sécurisé | G29: Plafond 16 % PASS.
B30: =IF(AND(TOG_PERIN="Oui",$F$6>="B"),"✓","") | C30: PER individuel | E30: =IF(AND(TOG_PERIN="Oui",$F$6>="B"),M_PERIN,"") | F30: 🟢 Sécurisé | G30: Versement déductible IR. Fiscalité différée à la sortie.
B31: =IF(AND(TOG_AVANTAGES="Oui",$F$6>="C"),"✓","") | C31: Avantages en nature | E31: =IF(AND(TOG_AVANTAGES="Oui",$F$6>="C"),M_AVANTAGES,"") | F31: 🟠 À valider | G31: Évaluation forfait vs réel - vérifier conformité arrêté 25/12/2002.
B32: =IF(AND(TOG_TR="Oui",$F$6>="B"),"✓","") | C32: Tickets restaurant | E32: =IF(AND(TOG_TR="Oui",$F$6>="B"),M_TR,"") | F32: 🟢 Sécurisé | G32: Part employeur exo ≤ 7,26 €/titre (60 % max).
B33: =IF(AND(TOG_CESU="Oui",$F$6>="B"),"✓","") | C33: CESU préfinancé | E33: =IF(AND(TOG_CESU="Oui",$F$6>="B"),M_CESU,"") | F33: 🟢 Sécurisé | G33: Exo ≤ 2 540 €/an/salarié.
B34: =IF(AND(TOG_CADO="Oui",$F$6>="C"),"✓","") | C34: Chèques cadeaux & vacances | E34: =IF(AND(TOG_CADO="Oui",$F$6>="C"),M_CADO,"") | F34: 🟠 À valider | G34: Tolérance URSSAF - non opposable de droit ; respecter les seuils.
B35: =IF(AND(TOG_MUTUELLE="Oui",$F$6>="B"),"✓","") | C35: Mutuelle / prévoyance | E35: =IF(AND(TOG_MUTUELLE="Oui",$F$6>="B"),M_MUTUELLE,"") | F35: 🟢 Sécurisé | G35: Contrat collectif obligatoire. Part patronale CSG/CRDS.
B36: =IF(AND(TOG_IK="Oui",$F$6>="C"),"✓","") | C36: Indemnités kilométriques | E36: =IF(AND(TOG_IK="Oui",$F$6>="C"),M_IK,"") | F36: 🟠 À valider | G36: Respecter le barème fiscal annuel ; justifier les déplacements.
B37: =IF(AND(TOG_CASHBACK="Oui",$F$6>="D"),"✓","") | C37: 💸 Cashback (programme partenaire) | E37: =IF(AND(TOG_CASHBACK="Oui",$F$6>="D"),M_CASHBACK,"") | F37: =CASHBACK_BADGE | G37: Risque selon mode de déploiement (cf. Profil §7) - note technique en feuille « 13. Sources ».
B38: Note : la rémunération directe (salaire/dividendes) absorbe le solde de l'enveloppe = ENVELOPPE − somme des dispositifs ci-dessus.
B40: ℹ La recommandation de stratégie est basée sur le net dirigeant maximal. Le scoring (podium ci-dessus) sert à comparer les dispositifs individuellement - il n'influence pas la sélection de la stratégie.
B41: =IF(AND(TOG_CASHBACK="Oui",$F$6>="D"),"⚠ Cashback inclus dans cette stratégie - Mode de déploiement défini en Profil §7. Susceptible de requalification URSSAF selon l'usage et la fréquence. Sécuriser avec le cabinet avant déploiement. Cf. note technique en feuille « 13. Sources ».","")
B44: Document préparé par [Cabinet] - Outil indicatif à usage professionnel ne se substituant pas à un conseil personnalisé. Paramètres fiscaux à mettre à jour annuellement. Cf. feuille « 13. Sources ».

Sheet 3. Mode emploi
A1: 3. Mode d'emploi | H1: ↩ Retour sommaire
A2: Comment utiliser l'outil - workflow recommandé.
B4: WORKFLOW RECOMMANDÉ
B5: Étape 1 | C5: Vérifier les paramètres fiscaux (feuille « 4. Paramètres »). Mettre à jour les cellules jaunes si nécessaire (changements LF / PLFSS de l'année).
B6: Étape 2 | C6: Saisir le profil du client (feuille « 5. Profil ») : forme juridique, foyer fiscal, enveloppe à arbitrer, et activer/désactiver les dispositifs souhaités.
B7: Étape 3 | C7: Consulter le comparateur (feuille « 6. Comparateur ») pour identifier les dispositifs les plus efficaces (ratio net/coût).
B8: Étape 4 | C8: Approfondir avec le module population (feuilles 6 à 9) correspondant au régime social du client.
B9: Étape 5 | C9: Modéliser 4 stratégies à enveloppe constante (feuille « 11. Arbitrage ») et choisir la combinaison optimale.
B10: Étape 6 | C10: Présenter la synthèse dirigeant (feuille « 12. Synthèse ») au client. Imprimer ou exporter en PDF.
B12: LÉGENDE DES COULEURS
B13: Cellule bleue / fond jaune clair | C13: Input modifiable par l'utilisateur (montants, choix client).
B14: Cellule bleue / fond jaune marqué | C14: Paramètre fiscal à mettre à jour annuellement.
B15: Cellule noire | C15: Cellule de calcul / formule dérivée - ne pas modifier.
B16: Texte vert | C16: Lien vers une autre feuille (defined name ou référence inter-feuilles).
B17: Bandeau bleu marine | C17: En-tête de section.
B19: ONGLETS - CODES COULEUR
B20: Gris | C20: Page de garde, mode d'emploi, sources & disclaimer
B21: Violet | C21: Référentiel fiscal & social (paramètres)
B22: Orange | C22: Inputs / profil client
B23: Bleu marine | C23: Modules de calcul (comparateur + modules par population + arbitrage)
B24: Vert | C24: Synthèse dirigeant - livrable client
B26: EXPORT PDF & PERSONNALISATION CABINET
B27: 1. Renommer le fichier | C27: Avant export, renommer le classeur sous la forme « [Nom_Cabinet]_Outil_arbitrage_[ClientX]_v13.xlsx ». Ce nom apparaîtra automatiquement dans le pied de page de chaque page imprimée (signature cabinet).
B28: 2. Saisir les inputs cabinet | C28: En feuille « 5. Profil » section 1 : renseigner « Cabinet », « Expert-comptable en charge » et « Nom du client ». Ces valeurs se propagent automatiquement sur la page de garde et la synthèse.
B29: 3. Générer le PDF | C29: Fichier → Exporter → Créer un document PDF/XPS. Dans « Options », cocher « Feuilles » et sélectionner manuellement l'ordre suivant : 1. Garde / 2. Dashboard / 12. Synthèse / Scénarios A vs B (si pertinent) / 11. Arbitrage / 13. Sources.
B30: 4. Personnaliser le footer (optionnel) | C30: Pour ajouter un libellé spécifique (ex : « Cabinet Dupont - Confidentiel ») : Mise en page → Pied de page → modifier le bloc gauche. Le réglage est conservé sur toutes les feuilles configurées pour l'export.
A33: Outil indicatif à usage professionnel - ne se substitue pas à un conseil personnalisé. Paramètres fiscaux à mettre à jour annuellement (cf. feuille « 13. Sources »).

Sheet 4. Paramètres
A1: 3. Paramètres fiscaux & sociaux | H1: ↩ Retour sommaire
A2: Référentiel 2025 - à mettre à jour annuellement (cellules jaunes)
B4: 1. PLAFOND DE LA SÉCURITÉ SOCIALE (PASS)
B5: Libellé | C5: Valeur | E5: Source / référence
B6: PASS annuel 2026 (€) | C6: 48060 | E6: Arrêté du 22/12/2025 - JORF du 23/12/2025 (+2,0 % vs 2025)
B7: PMSS (mensuel) (€) | C7: =C6/12 | E7: Calculé : PASS / 12 = 4 005 € en 2026
B9: 2. BARÈME IMPÔT SUR LE REVENU 2026 (revenus 2025)
B10: Tranche | C10: Plafond haut (€) | D10: Taux | E10: Source
B11: Jusqu'à | C11: 11600 | D11: 0 | E11: CGI art. 197 - LF 2025 (revalorisation +1,8 %). Plafonnement quotient familial : 1 791 €/demi-part (CGI art. 197, I-2).
B12: De 11 601 à | C12: 29579 | D12: 0.11
B13: De 29 580 à | C13: 84577 | D13: 0.3
B14: De 84 578 à | C14: 181917 | D14: 0.41
B15: Au-delà de 181 917 | C15: 1000000000000 | D15: 0.45
B17: 3. CSG / CRDS & PRÉLÈVEMENTS SOCIAUX
B18: Libellé | C18: Taux | E18: Source
B19: CSG sur revenus d'activité - part déductible | C19: 0.068 | E19: CSS art. L.136-8, BOI-RSA-BASE-30-30
B20: CSG sur revenus d'activité - part non déductible | C20: 0.024 | E20: CSS art. L.136-8
B21: CRDS sur revenus d'activité (non déductible) | C21: 0.005 | E21: Ordonnance n°96-50 du 24/01/1996
B22: CSG/CRDS revenus d'activité - TOTAL | C22: 0.097 | E22: Calculé
B23: Assiette CSG/CRDS sur salaire (% du brut) | C23: 0.9825 | E23: Abattement de 1,75 % sur ≤4 PASS - CSS art. L.136-2
B24: CSG sur revenus du capital - part déductible 2026 | C24: 0.068 | E24: CSS art. L.136-6 - taux dérog. 9,2 % maintenu sur fonciers, AV
B25: Prélèvements sociaux sur revenus du capital 2026 - TOTAL | C25: 0.186 | E25: LFSS 2026 art. 12 : CSG 10,6 % + CRDS 0,5 % + PS 7,5 % = 18,6 % (vs 17,2 % avant)
B27: 4. COTISATIONS SOCIALES - TAUX MOYENS INDICATIFS
B28: Régime / nature | C28: Taux | E28: Précision / source
B29: Assimilé salarié - cotisations patronales (taux moyen, dirigeant cadre) | C29: 0.42 | E29: Hors réduction Fillon (dirigeant non éligible). Variable selon T1/T2 et conventions.
B30: Assimilé salarié - cotisations salariales hors CSG/CRDS | C30: 0.12 | E30: Retraite, prévoyance, AGIRC-ARRCO. Pas de cotisation chômage pour mandataires.
B31: TNS - taux global de cotisations (sur rémunération nette) | C31: 0.45 | E31: URSSAF (maladie, AF, CSG/CRDS) + retraite (RCI/CIPAV) + invalidité-décès. Variable selon revenu.
B32: Profession libérale BNC - taux global indicatif | C32: 0.45 | E32: URSSAF + caisse de retraite (CIPAV, CARMF, CARPV…). Variable selon profession.
B34: 5. FORFAIT SOCIAL (loi PACTE)
B35: Dispositif × effectif | C35: Taux | E35: Source
B36: Participation - < 50 salariés | C36: 0 | E36: CSS art. L.137-15 - exonéré loi PACTE 2019
B37: Participation - 50 à 249 salariés | C37: 0.2 | E37: CSS art. L.137-16 (taux normal, sauf accord conventionnel)
B38: Participation - ≥ 250 salariés | C38: 0.2 | E38: CSS art. L.137-16
B39: Intéressement - < 250 salariés | C39: 0 | E39: CSS art. L.137-15 - exonéré loi PACTE 2019
B40: Intéressement - ≥ 250 salariés | C40: 0.2 | E40: CSS art. L.137-16
B41: Abondement employeur PEE/PERCO - < 50 sal. | C41: 0 | E41: CSS art. L.137-15
B42: Abondement employeur PEE/PERCO - ≥ 50 sal. | C42: 0.2 | E42: CSS art. L.137-16
B44: 6. PLAFONDS DES DISPOSITIFS
B45: Dispositif | C45: Plafond / formule | E45: Source
B46: Participation - plafond individuel (75 % PASS) | C46: =0.75*PASS_2025 | E46: C. trav. art. L.3324-5
...

Sheet 5. Profil
A1: 4. Profil client | H1: ↩ Retour sommaire
A2: Saisir le profil du dirigeant / client. Les cellules bleues sont à compléter.
B4: 1. IDENTITÉ DU CLIENT
B5: Nom du client / dénomination sociale | C5: [À renseigner]
B6: Référence dossier | C6: [Réf. cabinet]
B7: Date de la simulation | C7: =TODAY()
B8: Expert-comptable en charge | C8: [Nom collaborateur]
B9: Cabinet | C9: [Nom du cabinet]
B11: 2. STRUCTURE & RÉGIME SOCIAL
B12: Forme juridique | C12: SAS / SASU | E12: Liste déroulante. Choisir la forme du client.
B13: Régime social applicable | C13: =IF(C12="SAS / SASU","Assimilé salarié",IF(C12="SARL (gérance minoritaire)","Assimilé salarié",IF(C12="SARL (gérance majoritaire)","TNS",IF(C12="EURL (gérant associé unique)","TNS",IF(C12="EI (entrepreneur individuel)","TNS",IF(C12="EI à l'IS","TNS",IF(C12="SELARL","TNS (libéral)",IF(C12="SELAS","Assimilé salarié (libéral)",IF(C12="SCP","TNS (libéral)",IF(C12="Salarié (sans structure)","Salarié","À préciser")))))))))) | E13: Déduit automatiquement de la forme juridique.
B14: Effectif de l'entreprise | C14: 11-49 salariés | E14: Seuils légaux : 11 (mutuelle obli.), 50 (participation obli., forfait social), 250 (forfait intéressement). Cf. feuille « 4. Paramètres » §5.
B15: Part de capital détenue par le dirigeant (pour TNS) | C15: 0.5 | E15: Pour TNS : la fraction des dividendes excédant 10 % du (capital social + primes + CC associé) est soumise à cotisations TNS.
B16: Capital social + primes + CCA (€) [TNS uniquement] | C16: 10000 | E16: Base de calcul du seuil 10 %. Au-delà, la fraction de dividendes est requalifiée en rémunération TNS (cotisations ~45 % + IR au barème) au lieu du PFU. Ignoré pour assimilé salarié / salarié. CGI art. L. 131-6 al. 8 CSS, jurisprudence Cass. soc. 2018.
B18: 3. FOYER FISCAL
B19: Situation familiale | C19: Marié / pacsé
B20: Nombre de parts fiscales | C20: 2 | E20: 1 / 2 / 2,5 / 3… selon situation et nombre d'enfants. Plafonnement quotient familial : 1 807 €/demi-part (2026).
B21: Autres revenus imposables du foyer (€/an) | C21: 0 | E21: Salaires conjoint, revenus fonciers, BIC/BNC tiers… au barème. Pour le TMI marginal réel.
B22: Dividendes bruts perçus par le foyer (€/an) | C22: 0 | E22: Distributions effectives au foyer (hors enveloppe arbitrage). Entrent dans le RFR au PFU pour activer correctement la CDHR.
B23: Situation particulière (plafond QF spécifique) | C23: Aucune (cas général) | E23: Sélectionner si applicable : ajuste le plafond du QF (cf. Paramètres §9). Parent isolé : 4 262 € sur 1ère personne à charge. Veuf : plafond cumulé 5 625 €. Invalide : 3 608 €.
B25: 4. ENVELOPPE À ARBITRER
B26: Mode de pilotage | C26: Coût employeur global
B27: Enveloppe (€/an) | C27: 120000 | E27: Coût total annuel pour la société (charges incluses), ou cible nette dirigeant selon mode.
B28: Bénéfice IS de la société (€/an) | C28: 200000 | E28: Bénéfice avant rémunération du dirigeant. Sert au calcul des dividendes distribuables après IS.
B30: 5. ACTIVATION DES DISPOSITIFS
B31: Participation | C31: Oui | E31: Versement en N+1 sur résultat ; PEE/PERECO.
B32: Intéressement | C32: Oui | E32: Accord pluriannuel ; aléatoire et collectif.
B33: Abondement employeur PEE | C33: Oui | E33: Versement complémentaire aux dépôts du salarié.
B34: Abondement employeur PER collectif (PERECO) | C34: Oui | E34: Idem, plafond 16 % PASS.
B35: PER individuel (PERIN) | C35: Oui | E35: Versements déductibles du revenu imposable.
B36: Avantages en nature (véhicule, logement, NTIC) | C36: Oui | E36: Forfait ou réel - cf. arrêté 25/12/2002.
B37: Tickets restaurant | C37: Oui | E37: Exonération part employeur 7,26 €/titre (60 % max).
B38: CESU préfinancé | C38: Oui | E38: Exonéré jusqu'à 2 540 €/an/salarié.
B39: Chèques cadeaux & vacances | C39: Oui | E39: Tolérance URSSAF & exo chèques vacances.
B40: Mutuelle / prévoyance employeur | C40: Oui | E40: Contrat collectif obligatoire - déductible société.
B41: Indemnités kilométriques | C41: Non | E41: Sur la base du barème fiscal ou réelle.
B42: 💸 Cashback (programme partenaire) | C42: Non | E42: 🔴 Niveau de risque optimisé. Cf. note technique en feuille « 13. Sources ».
B44: 6. MONTANTS DES DISPOSITIFS (€/an, par bénéficiaire)
B45: Participation versée | C45: 1500
B46: Intéressement versé | C46: 2500
...

Sheet 6. Comparateur
A1: 5. Comparateur de dispositifs | O1: ↩ Retour sommaire
A2: Pour chaque dispositif activé, coût société, net dirigeant après IR et efficacité fiscale-sociale.
B4: A. PARAMÈTRES DÉRIVÉS DU PROFIL CLIENT
B5: Élément | C5: Valeur | D5: Mode de calcul
B6: Revenu imposable estimé par part (€) | C6: =IF(REGIME_SOCIAL="TNS",ENVELOPPE*0.7,IF(REGIME_SOCIAL="TNS (libéral)",ENVELOPPE*0.7,IF(REGIME_SOCIAL="Salarié",ENVELOPPE*0.55,ENVELOPPE*0.55)))/PARTS+AUTRES_REV/PARTS | D6: Estimé : enveloppe × ratio de net imposable (55 % salarié / 70 % TNS) / parts + autres rev./parts.
B7: TMI marginal estimé | C7: =IF(C6<=IR_PLAFOND_T1,0,IF(C6<=IR_PLAFOND_T2,IR_TAUX_T2,IF(C6<=IR_PLAFOND_T3,IR_TAUX_T3,IF(C6<=IR_PLAFOND_T4,IR_TAUX_T4,IR_TAUX_T5)))) | D7: Taux marginal applicable au revenu par part (cf. barème 2025).
B8: Forfait social - Participation (auto) | C8: =IF(OR(EFFECTIF="Sans salarié",EFFECTIF="1-10 salariés",EFFECTIF="11-49 salariés"),FS_PART_LT50,IF(EFFECTIF="50-249 salariés",FS_PART_50_249,IF(EFFECTIF="≥ 250 salariés",FS_PART_GE250,0))) | D8: Calculé selon effectif (cf. feuille « 4. Paramètres »).
B9: Forfait social - Intéressement (auto) | C9: =IF(EFFECTIF="≥ 250 salariés",FS_INT_GE250,FS_INT_LT250) | D9: Idem.
B10: Forfait social - Abondement (auto) | C10: =IF(OR(EFFECTIF="Sans salarié",EFFECTIF="1-10 salariés",EFFECTIF="11-49 salariés"),FS_ABO_LT50,FS_ABO_GE50) | D10: Idem.
B12: B. MATRICE DE RENTABILITÉ DES DISPOSITIFS - incluant scoring pondéré
B13: Dispositif | C13: Activé | D13: Montant input (€) | E13: Coût société (€) | F13: Coût bénéficiaire (€) | G13: Cotisations & PS (€) | H13: Net imposable (€) | I13: IR estimé (€) | J13: Net après IR (€) | K13: Ratio net / coût (%) | L13: Coef. risque | M13: Score ajusté (%) | N13: Top 3
B14: Salaire classique (référence) | C14: Réf. | D14: =ENVELOPPE/(1+TX_PATRONAL) | E14: =ENVELOPPE | F14: =0 | G14: =D14*TX_SALARIAL+D14*ASSIETTE_CSG_SAL*TX_CSG_CRDS_ACT | H14: =D14-D14*TX_SALARIAL-D14*ASSIETTE_CSG_SAL*0.068 | I14: =H14*$C$7 | J14: =D14-G14-I14 | K14: =IFERROR(J14/(E14+F14),0) | L14: =RISK_SALAIRE | M14: =K14*L14 | N14: -
B15: Dividendes - PFU 30 % | C15: Variable | D15: =10000 | E15: =D15/(1-TX_IS_NORMAL) | F15: =0 | G15: =D15*TX_PFU | H15: =0 | I15: =0 | J15: =D15-G15 | K15: =IFERROR(J15/E15,0) | L15: =RISK_DIVIDENDES | M15: =K15*L15 | N15: -
B16: Participation (placée 5 ans en PEE) | C16: =TOG_PARTICIPATION | D16: =M_PARTICIPATION | E16: =IF(C16="Oui",D16*(1+$C$8),0) | F16: =0 | G16: =IF(C16="Oui",D16*TX_CSG_CRDS_ACT,0) | H16: =0 | I16: =0 | J16: =IF(C16="Oui",D16-G16,0) | K16: =IFERROR(J16/E16,0) | L16: =RISK_PARTICIPATION | M16: =K16*L16 | N16: =IF(C16<>"Oui","",IF((SUMPRODUCT(($C$16:$C$27="Oui")*($M$16:$M$27>M16))+SUMPRODUCT(($C$16:$C$27="Oui")*($M$16:$M$27=M16)*(ROW($M$16:$M$27)<16)))=0,"🥇",IF((SUMPRODUCT(($C$16:$C$27="Oui")*($M$16:$M$27>M16))+SUMPRODUCT(($C$16:$C$27="Oui")*($M$16:$M$27=M16)*(ROW($M$16:$M$27)<16)))=1,"🥈",IF((SUMPRODUCT(($C$16:$C$27="Oui")*($M$16:$M$27>M16))+SUMPRODUCT(($C$16:$C$27="Oui")*($M$16:$M$27=M16)*(ROW($M$16:$M$27)<16)))=2,"🥉",""))))
B17: Intéressement (placé 5 ans en PEE) | C17: =TOG_INTERESSEMENT | D17: =M_INTERESSEMENT | E17: =IF(C17="Oui",D17*(1+$C$9),0) | F17: =0 | G17: =IF(C17="Oui",D17*TX_CSG_CRDS_ACT,0) | H17: =0 | I17: =0 | J17: =IF(C17="Oui",D17-G17,0) | K17: =IFERROR(J17/E17,0) | L17: =RISK_INTERESSEMENT | M17: =K17*L17 | N17: =IF(C17<>"Oui","",IF((SUMPRODUCT(($C$16:$C$27="Oui")*($M$16:$M$27>M17))+SUMPRODUCT(($C$16:$C$27="Oui")*($M$16:$M$27=M17)*(ROW($M$16:$M$27)<17)))=0,"🥇",IF((SUMPRODUCT(($C$16:$C$27="Oui")*($M$16:$M$27>M17))+SUMPRODUCT(($C$16:$C$27="Oui")*($M$16:$M$27=M17)*(ROW($M$16:$M$27)<17)))=1,"🥈",IF((SUMPRODUCT(($C$16:$C$27="Oui")*($M$16:$M$27>M17))+SUMPRODUCT(($C$16:$C$27="Oui")*($M$16:$M$27=M17)*(ROW($M$16:$M$27)<17)))=2,"🥉",""))))
B18: Abondement employeur PEE | C18: =TOG_ABO_PEE | D18: =M_ABO_PEE | E18: =IF(C18="Oui",D18*(1+$C$10),0) | F18: =0 | G18: =IF(C18="Oui",D18*TX_CSG_CRDS_ACT,0) | H18: =0 | I18: =0 | J18: =IF(C18="Oui",D18-G18,0) | K18: =IFERROR(J18/E18,0) | L18: =RISK_ABO_PEE | M18: =K18*L18 | N18: =IF(C18<>"Oui","",IF((SUMPRODUCT(($C$16:$C$27="Oui")*($M$16:$M$27>M18))+SUMPRODUCT(($C$16:$C$27="Oui")*($M$16:$M$27=M18)*(ROW($M$16:$M$27)<18)))=0,"🥇",IF((SUMPRODUCT(($C$16:$C$27="Oui")*($M$16:$M$27>M18))+SUMPRODUCT(($C$16:$C$27="Oui")*($M$16:$M$27=M18)*(ROW($M$16:$M$27)<18)))=1,"🥈",IF((SUMPRODUCT(($C$16:$C$27="Oui")*($M$16:$M$27>M18))+SUMPRODUCT(($C$16:$C$27="Oui")*($M$16:$M$27=M18)*(ROW($M$16:$M$27)<18)))=2,"🥉",""))))
B19: Abondement employeur PER collectif | C19: =TOG_ABO_PER | D19: =M_ABO_PER | E19: =IF(C19="Oui",D19*(1+$C$10),0) | F19: =0 | G19: =IF(C19="Oui",D19*TX_CSG_CRDS_ACT,0) | H19: =0 | I19: =0 | J19: =IF(C19="Oui",D19-G19,0) | K19: =IFERROR(J19/E19,0) | L19: =RISK_ABO_PER | M19: =K19*L19 | N19: =IF(C19<>"Oui","",IF((SUMPRODUCT(($C$16:$C$27="Oui")*($M$16:$M$27>M19))+SUMPRODUCT(($C$16:$C$27="Oui")*($M$16:$M$27=M19)*(ROW($M$16:$M$27)<19)))=0,"🥇",IF((SUMPRODUCT(($C$16:$C$27="Oui")*($M$16:$M$27>M19))+SUMPRODUCT(($C$16:$C$27="Oui")*($M$16:$M$27=M19)*(ROW($M$16:$M$27)<19)))=1,"🥈",IF((SUMPRODUCT(($C$16:$C$27="Oui")*($M$16:$M$27>M19))+SUMPRODUCT(($C$16:$C$27="Oui")*($M$16:$M$27=M19)*(ROW($M$16:$M$27)<19)))=2,"🥉",""))))
B20: PER individuel (versement déductible) | C20: =TOG_PERIN | D20: =M_PERIN | E20: =0 | F20: =IF(C20="Oui",D20*(1-$C$7),0) | G20: =0 | H20: =IF(C20="Oui",-D20,0) | I20: =IF(C20="Oui",-D20*$C$7,0) | J20: =IF(C20="Oui",D20-F20,0) | K20: =IFERROR(J20/MAX(F20,1),0) | L20: =RISK_PERIN | M20: =K20*L20 | N20: =IF(C20<>"Oui","",IF((SUMPRODUCT(($C$16:$C$27="Oui")*($M$16:$M$27>M20))+SUMPRODUCT(($C$16:$C$27="Oui")*($M$16:$M$27=M20)*(ROW($M$16:$M$27)<20)))=0,"🥇",IF((SUMPRODUCT(($C$16:$C$27="Oui")*($M$16:$M$27>M20))+SUMPRODUCT(($C$16:$C$27="Oui")*($M$16:$M$27=M20)*(ROW($M$16:$M$27)<20)))=1,"🥈",IF((SUMPRODUCT(($C$16:$C$27="Oui")*($M$16:$M$27>M20))+SUMPRODUCT(($C$16:$C$27="Oui")*($M$16:$M$27=M20)*(ROW($M$16:$M$27)<20)))=2,"🥉",""))))
B21: Avantages en nature (véhicule, NTIC...) | C21: =TOG_AVANTAGES | D21: =M_AVANTAGES | E21: =IF(C21="Oui",D21*(1+TX_PATRONAL),0) | F21: =0 | G21: =IF(C21="Oui",D21*(TX_SALARIAL+ASSIETTE_CSG_SAL*0.068),0) | H21: =IF(C21="Oui",D21*(1-TX_SALARIAL-ASSIETTE_CSG_SAL*0.068),0) | I21: =IF(C21="Oui",H21*$C$7,0) | J21: =IF(C21="Oui",D21-G21-I21,0) | K21: =IFERROR(J21/E21,0) | L21: =RISK_AVANTAGES | M21: =K21*L21 | N21: =IF(C21<>"Oui","",IF((SUMPRODUCT(($C$16:$C$27="Oui")*($M$16:$M$27>M21))+SUMPRODUCT(($C$16:$C$27="Oui")*($M$16:$M$27=M21)*(ROW($M$16:$M$27)<21)))=0,"🥇",IF((SUMPRODUCT(($C$16:$C$27="Oui")*($M$16:$M$27>M21))+SUMPRODUCT(($C$16:$C$27="Oui")*($M$16:$M$27=M21)*(ROW($M$16:$M$27)<21)))=1,"🥈",IF((SUMPRODUCT(($C$16:$C$27="Oui")*($M$16:$M$27>M21))+SUMPRODUCT(($C$16:$C$27="Oui")*($M$16:$M$27=M21)*(ROW($M$16:$M$27)<21)))=2,"🥉",""))))
B22: Tickets restaurant (part employeur exonérée) | C22: =TOG_TR | D22: =M_TR | E22: =IF(C22="Oui",D22,0) | F22: =0 | G22: =0 | H22: =0 | I22: =0 | J22: =IF(C22="Oui",D22,0) | K22: =IFERROR(J22/E22,0) | L22: =RISK_TR | M22: =K22*L22 | N22: =IF(C22<>"Oui","",IF((SUMPRODUCT(($C$16:$C$27="Oui")*($M$16:$M$27>M22))+SUMPRODUCT(($C$16:$C$27="Oui")*($M$16:$M$27=M22)*(ROW($M$16:$M$27)<22)))=0,"🥇",IF((SUMPRODUCT(($C$16:$C$27="Oui")*($M$16:$M$27>M22))+SUMPRODUCT(($C$16:$C$27="Oui")*($M$16:$M$27=M22)*(ROW($M$16:$M$27)<22)))=1,"🥈",IF((SUMPRODUCT(($C$16:$C$27="Oui")*($M$16:$M$27>M22))+SUMPRODUCT(($C$16:$C$27="Oui")*($M$16:$M$27=M22)*(ROW($M$16:$M$27)<22)))=2,"🥉",""))))
B23: CESU préfinancé (exonéré ≤ 2 540 €) | C23: =TOG_CESU | D23: =M_CESU | E23: =IF(C23="Oui",D23,0) | F23: =0 | G23: =0 | H23: =0 | I23: =0 | J23: =IF(C23="Oui",D23,0) | K23: =IFERROR(J23/E23,0) | L23: =RISK_CESU | M23: =K23*L23 | N23: =IF(C23<>"Oui","",IF((SUMPRODUCT(($C$16:$C$27="Oui")*($M$16:$M$27>M23))+SUMPRODUCT(($C$16:$C$27="Oui")*($M$16:$M$27=M23)*(ROW($M$16:$M$27)<23)))=0,"🥇",IF((SUMPRODUCT(($C$16:$C$27="Oui")*($M$16:$M$27>M23))+SUMPRODUCT(($C$16:$C$27="Oui")*($M$16:$M$27=M23)*(ROW($M$16:$M$27)<23)))=1,"🥈",IF((SUMPRODUCT(($C$16:$C$27="Oui")*($M$16:$M$27>M23))+SUMPRODUCT(($C$16:$C$27="Oui")*($M$16:$M$27=M23)*(ROW($M$16:$M$27)<23)))=2,"🥉",""))))
B24: Chèques cadeaux & vacances (tolérance URSSAF) | C24: =TOG_CADO | D24: =M_CADO | E24: =IF(C24="Oui",D24,0) | F24: =0 | G24: =0 | H24: =0 | I24: =0 | J24: =IF(C24="Oui",D24,0) | K24: =IFERROR(J24/E24,0) | L24: =RISK_CADO | M24: =K24*L24 | N24: =IF(C24<>"Oui","",IF((SUMPRODUCT(($C$16:$C$27="Oui")*($M$16:$M$27>M24))+SUMPRODUCT(($C$16:$C$27="Oui")*($M$16:$M$27=M24)*(ROW($M$16:$M$27)<24)))=0,"🥇",IF((SUMPRODUCT(($C$16:$C$27="Oui")*($M$16:$M$27>M24))+SUMPRODUCT(($C$16:$C$27="Oui")*($M$16:$M$27=M24)*(ROW($M$16:$M$27)<24)))=1,"🥈",IF((SUMPRODUCT(($C$16:$C$27="Oui")*($M$16:$M$27>M24))+SUMPRODUCT(($C$16:$C$27="Oui")*($M$16:$M$27=M24)*(ROW($M$16:$M$27)<24)))=2,"🥉",""))))
B25: Mutuelle / prévoyance employeur | C25: =TOG_MUTUELLE | D25: =M_MUTUELLE | E25: =IF(C25="Oui",D25,0) | F25: =0 | G25: =IF(C25="Oui",D25*TX_CSG_CRDS_ACT,0) | H25: =0 | I25: =0 | J25: =IF(C25="Oui",D25-G25,0) | K25: =IFERROR(J25/E25,0) | L25: =RISK_MUTUELLE | M25: =K25*L25 | N25: =IF(C25<>"Oui","",IF((SUMPRODUCT(($C$16:$C$27="Oui")*($M$16:$M$27>M25))+SUMPRODUCT(($C$16:$C$27="Oui")*($M$16:$M$27=M25)*(ROW($M$16:$M$27)<25)))=0,"🥇",IF((SUMPRODUCT(($C$16:$C$27="Oui")*($M$16:$M$27>M25))+SUMPRODUCT(($C$16:$C$27="Oui")*($M$16:$M$27=M25)*(ROW($M$16:$M$27)<25)))=1,"🥈",IF((SUMPRODUCT(($C$16:$C$27="Oui")*($M$16:$M$27>M25))+SUMPRODUCT(($C$16:$C$27="Oui")*($M$16:$M$27=M25)*(ROW($M$16:$M$27)<25)))=2,"🥉",""))))
B26: Indemnités kilométriques (barème fiscal) | C26: =TOG_IK | D26: =M_IK | E26: =IF(C26="Oui",D26,0) | F26: =0 | G26: =0 | H26: =0 | I26: =0 | J26: =IF(C26="Oui",D26,0) | K26: =IFERROR(J26/E26,0) | L26: =RISK_IK | M26: =K26*L26 | N26: =IF(C26<>"Oui","",IF((SUMPRODUCT(($C$16:$C$27="Oui")*($M$16:$M$27>M26))+SUMPRODUCT(($C$16:$C$27="Oui")*($M$16:$M$27=M26)*(ROW($M$16:$M$27)<26)))=0,"🥇",IF((SUMPRODUCT(($C$16:$C$27="Oui")*($M$16:$M$27>M26))+SUMPRODUCT(($C$16:$C$27="Oui")*($M$16:$M$27=M26)*(ROW($M$16:$M$27)<26)))=1,"🥈",IF((SUMPRODUCT(($C$16:$C$27="Oui")*($M$16:$M$27>M26))+SUMPRODUCT(($C$16:$C$27="Oui")*($M$16:$M$27=M26)*(ROW($M$16:$M$27)<26)))=2,"🥉",""))))
B27: 💸 Cashback (programme partenaire) | C27: =TOG_CASHBACK | D27: =M_CASHBACK | E27: =IF(C27="Oui",D27,0) | F27: =0 | G27: =0 | H27: =0 | I27: =0 | J27: =IF(C27="Oui",D27,0) | K27: =IFERROR(J27/MAX(E27,1),0) | L27: =RISK_CASHBACK | M27: =K27*L27 | N27: =IF(C27<>"Oui","",IF((SUMPRODUCT(($C$16:$C$27="Oui")*($M$16:$M$27>M27))+SUMPRODUCT(($C$16:$C$27="Oui")*($M$16:$M$27=M27)*(ROW($M$16:$M$27)<27)))=0,"🥇",IF((SUMPRODUCT(($C$16:$C$27="Oui")*($M$16:$M$27>M27))+SUMPRODUCT(($C$16:$C$27="Oui")*($M$16:$M$27=M27)*(ROW($M$16:$M$27)<27)))=1,"🥈",IF((SUMPRODUCT(($C$16:$C$27="Oui")*($M$16:$M$27>M27))+SUMPRODUCT(($C$16:$C$27="Oui")*($M$16:$M$27=M27)*(ROW($M$16:$M$27)<27)))=2,"🥉",""))))
B28: TOTAL DISPOSITIFS ACTIVÉS (hors salaire & dividendes) | D28: =SUM(D16:D27) | E28: =SUM(E16:E27) | F28: =SUM(F16:F27) | G28: =SUM(G16:G27) | H28: =SUM(H16:H27) | I28: =SUM(I16:I27) | J28: =SUM(J16:J27) | K28: =IFERROR(J28/(E28+F28),0)
B30: Notes & hypothèses simplificatrices
B31: • Participation, intéressement et abondements supposés placés ≥ 5 ans en PEE/PERECO → exonération d'IR (sortie en capital).
B32: • Versement PER individuel : économie IR matérialisée immédiatement au TMI estimé. La fiscalité de sortie (rente/capital) est différée et non modélisée ici.
B33: • Dividendes au PFU 30 % : pas de cotisations sociales sur les sociétés à l'IS, hors cas TNS gérant majoritaire (cf. module dédié).
B34: • Avantages en nature : forfait simplifié - adapter à la valeur réelle (véhicule, logement, NTIC) selon arrêté du 25/12/2002.
B35: • Cashback : assimilé à un transfert net non chargé. Le ratio rapporte le net au coût société effectif (souvent nul ou minime côté employeur).
B36: • Le taux marginal d'imposition (TMI) est estimé sur le seul revenu courant - les modules détaillés affinent par foyer.
A38: Outil indicatif à usage professionnel - ne se substitue pas à un conseil personnalisé. Paramètres fiscaux à mettre à jour annuellement (cf. feuille « 13. Sources »).

Sheet 7. Assimilé salarié
A1: 7. Module - Assimilé salarié | H1: ↩ Retour sommaire
A2: Président SAS/SASU, gérant minoritaire de SARL, président SELAS - régime général sécurité sociale.
B4: 1. INPUTS
B5: Salaire brut annuel (€) | C5: 80000 | E5: Saisir le brut annuel souhaité pour le dirigeant.
B6: Avantages en nature inclus dans le brut (€) | C6: 0 | E6: Véhicule, logement, NTIC… ajoutés au brut social et fiscal.
B7: Brut social total (€) | C7: =C5+C6 | E7: Assiette des cotisations.
B9: 2. COTISATIONS SALARIALES
B10: CSG/CRDS - assiette (98,25 % du brut social) | C10: =C7*ASSIETTE_CSG_SAL | E10: CSS art. L.136-2 - abattement 1,75 % pour ≤ 4 PASS.
B11: CSG déductible (6,80 %) | C11: =C10*0.068 | E11: Déductible du revenu imposable.
B12: CSG non déductible + CRDS (2,90 %) | C12: =C10*0.029 | E12: Non déductibles - réintégrées au revenu imposable.
B13: Cotisations salariales hors CSG/CRDS | C13: =C7*TX_SALARIAL | E13: Retraite, prévoyance - taux moyen paramétrable.
B14: Total prélèvements salariaux | C14: =C11+C12+C13
B15: Net après cotisations sociales | C15: =C7-C14 | E15: Avant impôt sur le revenu.
B17: 3. IMPÔT SUR LE REVENU
B18: Revenu salarial imposable (brut − cotis − CSG déd.) | C18: =C15+C12 | E18: Net après cotisations + CSG non déd. + CRDS (réintégrée fiscalement).
B19: Abattement 10 % frais professionnels (plafonné) | C19: =MIN(C18*0.1,14426) | E19: CGI art. 83 - plancher 504 €, plafond 14 426 € (LF 2026 art. 4).
B20: Revenu imposable net (€) | C20: =MAX(0,C18-C19)
B21: Revenu imposable foyer (avec autres revenus) | C21: =C20+AUTRES_REV
B22: Revenu imposable par part | C22: =C21/PARTS
B23: IR par part (barème) | C23: =IF(C22<=IR_PLAFOND_T1,0,IF(C22<=IR_PLAFOND_T2,(C22-IR_PLAFOND_T1)*IR_TAUX_T2,IF(C22<=IR_PLAFOND_T3,(C22-IR_PLAFOND_T2)*IR_TAUX_T3+(IR_PLAFOND_T2-IR_PLAFOND_T1)*IR_TAUX_T2,IF(C22<=IR_PLAFOND_T4,(C22-IR_PLAFOND_T3)*IR_TAUX_T4+(IR_PLAFOND_T3-IR_PLAFOND_T2)*IR_TAUX_T3+(IR_PLAFOND_T2-IR_PLAFOND_T1)*IR_TAUX_T2,(C22-IR_PLAFOND_T4)*IR_TAUX_T5+(IR_PLAFOND_T4-IR_PLAFOND_T3)*IR_TAUX_T4+(IR_PLAFOND_T3-IR_PLAFOND_T2)*IR_TAUX_T3+(IR_PLAFOND_T2-IR_PLAFOND_T1)*IR_TAUX_T2))))
B24: IR du foyer avec QF (avant plafond) | C24: =C23*PARTS
B25: IR sans QF (référence) | C25: =(IF((C21)/(IF(SITUATION="Marié / pacsé",2,1))<=IR_PLAFOND_T1,0,IF((C21)/(IF(SITUATION="Marié / pacsé",2,1))<=IR_PLAFOND_T2,((C21)/(IF(SITUATION="Marié / pacsé",2,1))-IR_PLAFOND_T1)*IR_TAUX_T2,IF((C21)/(IF(SITUATION="Marié / pacsé",2,1))<=IR_PLAFOND_T3,((C21)/(IF(SITUATION="Marié / pacsé",2,1))-IR_PLAFOND_T2)*IR_TAUX_T3+(IR_PLAFOND_T2-IR_PLAFOND_T1)*IR_TAUX_T2,IF((C21)/(IF(SITUATION="Marié / pacsé",2,1))<=IR_PLAFOND_T4,((C21)/(IF(SITUATION="Marié / pacsé",2,1))-IR_PLAFOND_T3)*IR_TAUX_T4+(IR_PLAFOND_T3-IR_PLAFOND_T2)*IR_TAUX_T3+(IR_PLAFOND_T2-IR_PLAFOND_T1)*IR_TAUX_T2,((C21)/(IF(SITUATION="Marié / pacsé",2,1))-IR_PLAFOND_T4)*IR_TAUX_T5+(IR_PLAFOND_T4-IR_PLAFOND_T3)*IR_TAUX_T4+(IR_PLAFOND_T3-IR_PLAFOND_T2)*IR_TAUX_T3+(IR_PLAFOND_T2-IR_PLAFOND_T1)*IR_TAUX_T2)))))*(IF(SITUATION="Marié / pacsé",2,1)) | E25: Calculé en supposant la situation de base (1 part célib / 2 parts marié).
B26: Plafonnement QF (excédent réintégré) | C26: =MAX(0,((C25)-(C24))-(IFERROR(IF(SITUATION_PART="Parent isolé (case T)",IF(((PARTS)-(IF(SITUATION="Marié / pacsé",2,1)))*2>=1,PLAF_QF_PARENT_ISOLE+MAX(0,((PARTS)-(IF(SITUATION="Marié / pacsé",2,1)))*2-1)*PLAF_QF_DEMI_PART,0),IF(SITUATION_PART="Personne seule ayant élevé un enfant ≥ 5 ans (case L)",IF(((PARTS)-(IF(SITUATION="Marié / pacsé",2,1)))*2>=1,PLAF_QF_PERS_SEULE_L+MAX(0,((PARTS)-(IF(SITUATION="Marié / pacsé",2,1)))*2-1)*PLAF_QF_DEMI_PART,0),IF(SITUATION_PART="Veuf avec enfants à charge",IF(((PARTS)-(IF(SITUATION="Marié / pacsé",2,1)))*2>=1,PLAF_QF_VEUF+MAX(0,((PARTS)-(IF(SITUATION="Marié / pacsé",2,1)))*2-1)*PLAF_QF_DEMI_PART,0),IF(SITUATION_PART="Ancien combattant > 74 ans ou invalide",IF(((PARTS)-(IF(SITUATION="Marié / pacsé",2,1)))*2>=1,PLAF_QF_INVALIDE+MAX(0,((PARTS)-(IF(SITUATION="Marié / pacsé",2,1)))*2-1)*PLAF_QF_DEMI_PART,0),PLAF_QF_DEMI_PART*((PARTS)-(IF(SITUATION="Marié / pacsé",2,1)))*2)))),PLAF_QF_DEMI_PART*((PARTS)-(IF(SITUATION="Marié / pacsé",2,1)))*2))) | E26: Cap 1 791 €/demi-part excédentaire (CGI art. 197, I-2°).
B27: IR du foyer après plafonnement QF | C27: =C24+C26
B28: RFR élargi (revenu imposable + dividendes PFU) | C28: =C21+DIVIDENDES_FOYER | E28: Inclut les dividendes au PFU saisis en Profil §3 - assiette commune CEHR + CDHR (CGI art. 223 sexies et 224).
B29: CEHR (contribution exceptionnelle hauts revenus) | C29: =IF(SITUATION="Marié / pacsé",IF(C28<=CEHR_SEUIL_M1,0,IF(C28<=CEHR_SEUIL_M2,(C28-CEHR_SEUIL_M1)*CEHR_TX_1,(CEHR_SEUIL_M2-CEHR_SEUIL_M1)*CEHR_TX_1+(C28-CEHR_SEUIL_M2)*CEHR_TX_2)),IF(C28<=CEHR_SEUIL_C1,0,IF(C28<=CEHR_SEUIL_C2,(C28-CEHR_SEUIL_C1)*CEHR_TX_1,(CEHR_SEUIL_C2-CEHR_SEUIL_C1)*CEHR_TX_1+(C28-CEHR_SEUIL_C2)*CEHR_TX_2))) | E29: CGI art. 223 sexies - assise sur le RFR élargi (incluant les dividendes au PFU).
B30: IR forfaitaire sur dividendes (PFU 12,8 %) | C30: =DIVIDENDES_FOYER*0.128 | E30: Part IR du PFU. Compte dans le numérateur du plancher 20 % de la CDHR.
B31: CDHR (contribution différentielle hauts revenus) | C31: =IF(C28<=IF(SITUATION="Marié / pacsé",CDHR_SEUIL_M,CDHR_SEUIL_C),0,(MAX(0,CDHR_TAUX_PLANCHER*C28-(((C27+C30))+(C29))))*(MIN(1,MAX(0,(C28-(IF(SITUATION="Marié / pacsé",CDHR_SEUIL_M,CDHR_SEUIL_C)))/((IF(SITUATION="Marié / pacsé",CDHR_SEUIL_M_HAUT,CDHR_SEUIL_C_HAUT))-(IF(SITUATION="Marié / pacsé",CDHR_SEUIL_M,CDHR_SEUIL_C))))))) | E31: CGI art. 224 - LF 2025 art. 10, pérennisée LF 2026 art. 2. Plancher 20 % d'impôt effectif sur RFR > 250 k€ (célib) / 500 k€ (couple). Modélisation simplifiée - sans lissage ni retraitement revenus exceptionnels.
B32: Total impôts foyer (IR + CEHR + CDHR) | C32: =C27+C29+C31 | E32: Hors IR PFU sur dividendes - celui-ci reste imputé au foyer hors enveloppe arbitrage.
B33: Taux moyen IR foyer (IR + CEHR + CDHR) / Revenu imposable | C33: =IFERROR(C32/C21,0) | E33: Taux moyen effectif - réutilisé en Arbitrage pour aligner le calcul du net salarial sur le module sélectionné.
B34: Impôts imputables à la rémunération (prorata) | C34: =C32*IFERROR(C20/C21,0) | E34: IR + CEHR + CDHR imputés à la rémunération du dirigeant au prorata.
B36: 4. NET DIRIGEANT APRÈS IMPÔTS
B37: Net après cotisations sociales | C37: =C15
B38: (–) Impôts imputables (IR + CEHR + CDHR) | C38: =C34
B39: Net dirigeant après impôts (€) | C39: =C15-C34 | E39: Pouvoir d'achat net annuel du dirigeant, après IR (avec QF cappé), CEHR et CDHR.
B41: 5. COÛT EMPLOYEUR
B42: Cotisations patronales | C42: =C7*TX_PATRONAL | E42: Taux moyen paramétrable. Hors réduction Fillon (dirigeant non éligible).
B43: Coût employeur total (€) | C43: =C7+C42
B44: Ratio net dirigeant / coût employeur | C44: =IFERROR(C39/C43,0) | E44: Indicateur clé : combien de € de net pour 100 € de coût total.
B46: 6. ALTERNATIVE - DIVIDENDES (PFU 30 %)
...

Sheet 8. TNS
A1: 8. Module - Travailleur non-salarié (TNS) | H1: ↩ Retour sommaire
A2: Gérant majoritaire SARL/EURL, EI, EI à l'IS - régime social des indépendants (URSSAF + RCI/CIPAV).
B4: 1. INPUTS
B5: Rémunération nette annuelle souhaitée (€) | C5: 70000 | E5: Revenu net déclaré (après cotisations TNS, avant IR). Base de calcul des cotisations.
B6: Frais réels professionnels (€) | C6: 0 | E6: Frais déductibles BIC ou rémunération nette. 0 par défaut.
B8: 2. COTISATIONS TNS
B9: Taux global TNS (paramétrable) | C9: =TX_TNS | E9: Taux moyen sur le revenu net - variable selon revenu (cf. feuille « 4. Paramètres »).
B10: Cotisations TNS totales | C10: =C5*C9 | E10: URSSAF (maladie, AF, CSG/CRDS) + retraite + invalidité.
B11: Dont CSG déductible (6,80 % du net + cot.) | C11: =(C5+C10)*0.068 | E11: Déductible BIC mais réintégrée fiscalement pour calcul revenu imposable.
B12: Dont CSG/CRDS non déductible (2,90 %) | C12: =(C5+C10)*0.029
B14: 3. IMPÔT SUR LE REVENU
B15: Revenu net BIC/professionnel | C15: =C5-C6
B16: Revenu imposable (réintégration CSG non déd.) | C16: =C15+C12
B17: Revenu imposable foyer | C17: =C16+AUTRES_REV
B18: Revenu par part | C18: =C17/PARTS
B19: IR par part (barème) | C19: =IF(C18<=IR_PLAFOND_T1,0,IF(C18<=IR_PLAFOND_T2,(C18-IR_PLAFOND_T1)*IR_TAUX_T2,IF(C18<=IR_PLAFOND_T3,(C18-IR_PLAFOND_T2)*IR_TAUX_T3+(IR_PLAFOND_T2-IR_PLAFOND_T1)*IR_TAUX_T2,IF(C18<=IR_PLAFOND_T4,(C18-IR_PLAFOND_T3)*IR_TAUX_T4+(IR_PLAFOND_T3-IR_PLAFOND_T2)*IR_TAUX_T3+(IR_PLAFOND_T2-IR_PLAFOND_T1)*IR_TAUX_T2,(C18-IR_PLAFOND_T4)*IR_TAUX_T5+(IR_PLAFOND_T4-IR_PLAFOND_T3)*IR_TAUX_T4+(IR_PLAFOND_T3-IR_PLAFOND_T2)*IR_TAUX_T3+(IR_PLAFOND_T2-IR_PLAFOND_T1)*IR_TAUX_T2))))
B20: IR du foyer avec QF (avant plafond) | C20: =C19*PARTS
B21: IR sans QF (référence) | C21: =(IF((C17)/(IF(SITUATION="Marié / pacsé",2,1))<=IR_PLAFOND_T1,0,IF((C17)/(IF(SITUATION="Marié / pacsé",2,1))<=IR_PLAFOND_T2,((C17)/(IF(SITUATION="Marié / pacsé",2,1))-IR_PLAFOND_T1)*IR_TAUX_T2,IF((C17)/(IF(SITUATION="Marié / pacsé",2,1))<=IR_PLAFOND_T3,((C17)/(IF(SITUATION="Marié / pacsé",2,1))-IR_PLAFOND_T2)*IR_TAUX_T3+(IR_PLAFOND_T2-IR_PLAFOND_T1)*IR_TAUX_T2,IF((C17)/(IF(SITUATION="Marié / pacsé",2,1))<=IR_PLAFOND_T4,((C17)/(IF(SITUATION="Marié / pacsé",2,1))-IR_PLAFOND_T3)*IR_TAUX_T4+(IR_PLAFOND_T3-IR_PLAFOND_T2)*IR_TAUX_T3+(IR_PLAFOND_T2-IR_PLAFOND_T1)*IR_TAUX_T2,((C17)/(IF(SITUATION="Marié / pacsé",2,1))-IR_PLAFOND_T4)*IR_TAUX_T5+(IR_PLAFOND_T4-IR_PLAFOND_T3)*IR_TAUX_T4+(IR_PLAFOND_T3-IR_PLAFOND_T2)*IR_TAUX_T3+(IR_PLAFOND_T2-IR_PLAFOND_T1)*IR_TAUX_T2)))))*(IF(SITUATION="Marié / pacsé",2,1))
B22: Plafonnement QF (excédent réintégré) | C22: =MAX(0,((C21)-(C20))-(IFERROR(IF(SITUATION_PART="Parent isolé (case T)",IF(((PARTS)-(IF(SITUATION="Marié / pacsé",2,1)))*2>=1,PLAF_QF_PARENT_ISOLE+MAX(0,((PARTS)-(IF(SITUATION="Marié / pacsé",2,1)))*2-1)*PLAF_QF_DEMI_PART,0),IF(SITUATION_PART="Personne seule ayant élevé un enfant ≥ 5 ans (case L)",IF(((PARTS)-(IF(SITUATION="Marié / pacsé",2,1)))*2>=1,PLAF_QF_PERS_SEULE_L+MAX(0,((PARTS)-(IF(SITUATION="Marié / pacsé",2,1)))*2-1)*PLAF_QF_DEMI_PART,0),IF(SITUATION_PART="Veuf avec enfants à charge",IF(((PARTS)-(IF(SITUATION="Marié / pacsé",2,1)))*2>=1,PLAF_QF_VEUF+MAX(0,((PARTS)-(IF(SITUATION="Marié / pacsé",2,1)))*2-1)*PLAF_QF_DEMI_PART,0),IF(SITUATION_PART="Ancien combattant > 74 ans ou invalide",IF(((PARTS)-(IF(SITUATION="Marié / pacsé",2,1)))*2>=1,PLAF_QF_INVALIDE+MAX(0,((PARTS)-(IF(SITUATION="Marié / pacsé",2,1)))*2-1)*PLAF_QF_DEMI_PART,0),PLAF_QF_DEMI_PART*((PARTS)-(IF(SITUATION="Marié / pacsé",2,1)))*2)))),PLAF_QF_DEMI_PART*((PARTS)-(IF(SITUATION="Marié / pacsé",2,1)))*2)))
B23: IR du foyer après plafonnement QF | C23: =C20+C22
B24: RFR élargi (+ dividendes PFU) | C24: =C17+DIVIDENDES_FOYER
B25: CEHR | C25: =IF(SITUATION="Marié / pacsé",IF(C24<=CEHR_SEUIL_M1,0,IF(C24<=CEHR_SEUIL_M2,(C24-CEHR_SEUIL_M1)*CEHR_TX_1,(CEHR_SEUIL_M2-CEHR_SEUIL_M1)*CEHR_TX_1+(C24-CEHR_SEUIL_M2)*CEHR_TX_2)),IF(C24<=CEHR_SEUIL_C1,0,IF(C24<=CEHR_SEUIL_C2,(C24-CEHR_SEUIL_C1)*CEHR_TX_1,(CEHR_SEUIL_C2-CEHR_SEUIL_C1)*CEHR_TX_1+(C24-CEHR_SEUIL_C2)*CEHR_TX_2)))
B26: IR forfaitaire sur dividendes (PFU 12,8 %) | C26: =DIVIDENDES_FOYER*0.128
B27: CDHR (plancher 20 % impôt effectif) | C27: =IF(C24<=IF(SITUATION="Marié / pacsé",CDHR_SEUIL_M,CDHR_SEUIL_C),0,(MAX(0,CDHR_TAUX_PLANCHER*C24-(((C23+C26))+(C25))))*(MIN(1,MAX(0,(C24-(IF(SITUATION="Marié / pacsé",CDHR_SEUIL_M,CDHR_SEUIL_C)))/((IF(SITUATION="Marié / pacsé",CDHR_SEUIL_M_HAUT,CDHR_SEUIL_C_HAUT))-(IF(SITUATION="Marié / pacsé",CDHR_SEUIL_M,CDHR_SEUIL_C))))))) | E27: CGI art. 224 - modélisation simplifiée sans lissage. RFR retraité incluant dividendes PFU.
B28: Total impôts foyer (IR + CEHR + CDHR) | C28: =C23+C25+C27
B29: Taux moyen IR foyer (IR + CEHR + CDHR) / Revenu imposable | C29: =IFERROR(C28/C17,0)
B30: Taux moyen IR foyer (IR + CEHR + CDHR) / Revenu imposable | C30: =IFERROR(C29/C17,0)
B31: Taux moyen IR foyer (IR + CEHR + CDHR) / Revenu imposable | C31: =IFERROR(C30/C17,0)
B32: Impôts imputables à la rémunération (prorata) | C32: =C31*IFERROR(C16/C17,0)
B34: 4. NET TNS APRÈS IR
B35: Net dirigeant après IR (€) | C35: =C5-C32 | E35: Pouvoir d'achat net annuel du TNS.
B37: 5. COÛT POUR LA SOCIÉTÉ
B38: Coût total (rém. + cotisations TNS) (€) | C38: =C5+C10
B39: Ratio net dirigeant / coût total | C39: =IFERROR(C35/C38,0)
B41: 6. DIVIDENDES - SPÉCIFICITÉ TNS GÉRANT MAJORITAIRE
B42: Capital social + primes + CC associé (€) | C42: 100000 | E42: Base de calcul du seuil 10 % au-delà duquel les dividendes sont soumis cotisations TNS.
B43: Seuil 10 % (€) | C43: =C42*SEUIL_DIV_TNS | E43: CSS art. L.131-6, 3°.
B44: Dividendes bruts envisagés (€) | C44: 50000
B45: Fraction soumise cotisations TNS | C45: =MAX(0,C44-C43) | E45: Excédent au-delà du seuil - soumis cotisations TNS.
B46: Cotisations TNS sur dividendes | C46: =C45*C9
...

Sheet 9. Libéral
A1: 9. Module - Profession libérale | H1: ↩ Retour sommaire
A2: BNC (médecin, avocat, consultant…) ou SEL (SELARL/SELAS) - régimes spécifiques.
B4: 1. SCÉNARIO BNC (exercice individuel)
B5: Recettes annuelles (€) | C5: 150000
B6: Frais professionnels déductibles (€) | C6: 30000 | E6: Loyer cabinet, secrétariat, matériel, charges sociales déjà payées en N-1, etc.
B7: Bénéfice BNC | C7: =C5-C6
B8: Cotisations URSSAF + caisse de retraite | C8: =C7*TX_LIB | E8: CIPAV / CARMF / CARPV / CARCDSF / CARPIMKO / CNBF selon profession. TX_LIB est supposé inclure CSG/CRDS totales.
B9: Dont CSG/CRDS non déductible (2,90 % du bénéfice) | C9: =C7*0.029 | E9: Réintégrée dans l'assiette IR ci-dessous (CSG non déduc. + CRDS).
B10: Bénéfice net après cotisations | C10: =C7-C8
B11: Revenu imposable libéral (réintégration CSG non déd.) | C11: =C10+C9
B12: Revenu imposable foyer | C12: =C11+AUTRES_REV
B13: Revenu par part | C13: =C12/PARTS
B14: IR par part | C14: =IF(C13<=IR_PLAFOND_T1,0,IF(C13<=IR_PLAFOND_T2,(C13-IR_PLAFOND_T1)*IR_TAUX_T2,IF(C13<=IR_PLAFOND_T3,(C13-IR_PLAFOND_T2)*IR_TAUX_T3+(IR_PLAFOND_T2-IR_PLAFOND_T1)*IR_TAUX_T2,IF(C13<=IR_PLAFOND_T4,(C13-IR_PLAFOND_T3)*IR_TAUX_T4+(IR_PLAFOND_T3-IR_PLAFOND_T2)*IR_TAUX_T3+(IR_PLAFOND_T2-IR_PLAFOND_T1)*IR_TAUX_T2,(C13-IR_PLAFOND_T4)*IR_TAUX_T5+(IR_PLAFOND_T4-IR_PLAFOND_T3)*IR_TAUX_T4+(IR_PLAFOND_T3-IR_PLAFOND_T2)*IR_TAUX_T3+(IR_PLAFOND_T2-IR_PLAFOND_T1)*IR_TAUX_T2))))
B15: IR du foyer avec QF (avant plafond) | C15: =C14*PARTS
